Traceback (most recent call last):
  File "/usr/local/lib/python3.8/dist-packages/jupyter_cache/executors/utils.py", line 51, in single_nb_execution
    executenb(
  File "/usr/local/lib/python3.8/dist-packages/nbclient/client.py", line 1087, in execute
    return NotebookClient(nb=nb, resources=resources, km=km, **kwargs).execute()
  File "/usr/local/lib/python3.8/dist-packages/nbclient/util.py", line 74, in wrapped
    return just_run(coro(*args, **kwargs))
  File "/usr/local/lib/python3.8/dist-packages/nbclient/util.py", line 53, in just_run
    return loop.run_until_complete(coro)
  File "/usr/lib/python3.8/asyncio/base_events.py", line 616, in run_until_complete
    return future.result()
  File "/usr/local/lib/python3.8/dist-packages/nbclient/client.py", line 540, in async_execute
    await self.async_execute_cell(
  File "/usr/local/lib/python3.8/dist-packages/nbclient/client.py", line 832, in async_execute_cell
    self._check_raise_for_error(cell, exec_reply)
  File "/usr/local/lib/python3.8/dist-packages/nbclient/client.py", line 740, in _check_raise_for_error
    raise CellExecutionError.from_cell_and_msg(cell, exec_reply['content'])
nbclient.exceptions.CellExecutionError: An error occurred while executing the following cell:
------------------
cm = 'tae_h:64_z:16_drp:0.1_wd:0.001_lr:0.01_gamma:0.95_latest'
mod, metadata = load_model(keyword=cm, chkpt_id=-1)
mod.config.base_dir
------------------

[0;31m---------------------------------------------------------------------------[0m
[0;31mRuntimeError[0m                              Traceback (most recent call last)
[0;32m<ipython-input-3-f7e32e561ce6>[0m in [0;36m<module>[0;34m[0m
[1;32m      1[0m [0mcm[0m [0;34m=[0m [0;34m'tae_h:64_z:16_drp:0.1_wd:0.001_lr:0.01_gamma:0.95_latest'[0m[0;34m[0m[0;34m[0m[0m
[0;32m----> 2[0;31m [0mmod[0m[0;34m,[0m [0mmetadata[0m [0;34m=[0m [0mload_model[0m[0;34m([0m[0mkeyword[0m[0;34m=[0m[0mcm[0m[0;34m,[0m [0mchkpt_id[0m[0;34m=[0m[0;34m-[0m[0;36m1[0m[0;34m)[0m[0;34m[0m[0;34m[0m[0m
[0m[1;32m      3[0m [0mmod[0m[0;34m.[0m[0mconfig[0m[0;34m.[0m[0mbase_dir[0m[0;34m[0m[0;34m[0m[0m

[0;32m~/Dropbox/git/A1ToneDiscrimination/autoencoder/model_utils.py[0m in [0;36mload_model[0;34m(keyword, chkpt_id, strict, verbose, base_dir)[0m
[1;32m     58[0m [0;34m[0m[0m
[1;32m     59[0m     [0;32mif[0m [0;32mnot[0m [0mmatch[0m[0;34m:[0m[0;34m[0m[0;34m[0m[0m
[0;32m---> 60[0;31m         [0;32mraise[0m [0mRuntimeError[0m[0;34m([0m[0;34m'no match found for keyword: {:s}'[0m[0;34m.[0m[0mformat[0m[0;34m([0m[0mkeyword[0m[0;34m)[0m[0;34m)[0m[0;34m[0m[0;34m[0m[0m
[0m[1;32m     61[0m [0;34m[0m[0m
[1;32m     62[0m     [0mavailable_chkpts[0m [0;34m=[0m [0msorted[0m[0;34m([0m[0mos[0m[0;34m.[0m[0mlistdir[0m[0;34m([0m[0mmodel_dir[0m[0;34m)[0m[0;34m,[0m [0mkey[0m[0;34m=[0m[0;32mlambda[0m [0mx[0m[0;34m:[0m [0mint[0m[0;34m([0m[0mx[0m[0;34m)[0m[0;34m)[0m[0;34m[0m[0;34m[0m[0m

[0;31mRuntimeError[0m: no match found for keyword: tae_h:64_z:16_drp:0.1_wd:0.001_lr:0.01_gamma:0.95_latest
RuntimeError: no match found for keyword: tae_h:64_z:16_drp:0.1_wd:0.001_lr:0.01_gamma:0.95_latest

